<sdf version='1.7'>
  <world name='default'>
    <plugin name='gazebo_ros_power_monitor_controller' filename='libgazebo_ros_link_attacher.so'/>
    <light name='sun' type='directional'>
      <cast_shadows>1</cast_shadows>
      <pose>0 0 10 0 -0 0</pose>
      <diffuse>0.8 0.8 0.8 1</diffuse>
      <specular>0.2 0.2 0.2 1</specular>
      <attenuation>
        <range>1000</range>
        <constant>0.9</constant>
        <linear>0.01</linear>
        <quadratic>0.001</quadratic>
      </attenuation>
      <direction>-0.5 0.1 -0.9</direction>
      <spot>
        <inner_angle>0</inner_angle>
        <outer_angle>0</outer_angle>
        <falloff>0</falloff>
      </spot>
    </light>
    <model name='ground_plane'>
      <static>1</static>
      <link name='link'>
        <collision name='collision'>
          <geometry>
            <plane>
              <normal>0 0 1</normal>
              <size>100 100</size>
            </plane>
          </geometry>
          <surface>
            <contact>
              <collide_bitmask>65535</collide_bitmask>
              <ode/>
            </contact>
            <friction>
              <ode>
                <mu>100</mu>
                <mu2>50</mu2>
              </ode>
              <torsional>
                <ode/>
              </torsional>
            </friction>
            <bounce/>
          </surface>
          <max_contacts>10</max_contacts>
        </collision>
        <visual name='visual'>
          <cast_shadows>0</cast_shadows>
          <geometry>
            <plane>
              <normal>0 0 1</normal>
              <size>100 100</size>
            </plane>
          </geometry>
          <material>
            <script>
              <uri>file://media/materials/scripts/gazebo.material</uri>
              <name>Gazebo/Grey</name>
            </script>
          </material>
        </visual>
        <self_collide>0</self_collide>
        <enable_wind>0</enable_wind>
        <kinematic>0</kinematic>
      </link>
    </model>
    <gravity>0 0 -9.8</gravity>
    <magnetic_field>6e-06 2.3e-05 -4.2e-05</magnetic_field>
    <atmosphere type='adiabatic'/>
    <physics type='ode'>
      <max_step_size>0.001</max_step_size>
      <real_time_factor>1</real_time_factor>
      <real_time_update_rate>1000</real_time_update_rate>
    </physics>
    <scene>
      <ambient>0.4 0.4 0.4 1</ambient>
      <background>0.7 0.7 0.7 1</background>
      <shadows>1</shadows>
    </scene>
    <wind/>
    <spherical_coordinates>
      <surface_model>EARTH_WGS84</surface_model>
      <latitude_deg>0</latitude_deg>
      <longitude_deg>0</longitude_deg>
      <elevation>0</elevation>
      <heading_deg>0</heading_deg>
    </spherical_coordinates>
    <model name='ur5_base'>
      <static>1</static>
      <link name='top_plate'>
        <pose>0 0 0.775 0 -0 0</pose>
        <collision name='top_plate_collision'>
          <geometry>
            <box>
              <size>0.2 0.2 0.02</size>
            </box>
          </geometry>
          <surface>
            <contact>
              <collide_bitmask>1</collide_bitmask>
              <ode/>
            </contact>
            <bounce/>
            <friction>
              <torsional>
                <ode/>
              </torsional>
              <ode/>
            </friction>
          </surface>
          <max_contacts>10</max_contacts>
        </collision>
        <visual name='top_plate_visual'>
          <geometry>
            <box>
              <size>0.5 0.5 0.02</size>
            </box>
          </geometry>
          <material>
            <script>
              <uri>file://media/materials/scripts/gazebo.material</uri>
              <name>Gazebo/Grey</name>
            </script>
          </material>
        </visual>
        <self_collide>0</self_collide>
        <enable_wind>0</enable_wind>
        <kinematic>0</kinematic>
      </link>
      <link name='leg1'>
        <pose>0.22 0.22 0.285 0 -0 0</pose>
        <collision name='leg1_collision'>
          <geometry>
            <box>
              <size>0.04 0.04 1</size>
            </box>
          </geometry>
          <max_contacts>10</max_contacts>
          <surface>
            <contact>
              <ode/>
            </contact>
            <bounce/>
            <friction>
              <torsional>
                <ode/>
              </torsional>
              <ode/>
            </friction>
          </surface>
        </collision>
        <visual name='leg1_visual'>
          <geometry>
            <box>
              <size>0.04 0.04 1</size>
            </box>
          </geometry>
          <material>
            <script>
              <uri>file://media/materials/scripts/gazebo.material</uri>
              <name>Gazebo/Grey</name>
            </script>
          </material>
        </visual>
        <self_collide>0</self_collide>
        <enable_wind>0</enable_wind>
        <kinematic>0</kinematic>
      </link>
      <link name='leg2'>
        <pose>-0.22 0.22 0.285 0 -0 0</pose>
        <collision name='leg2_collision'>
          <geometry>
            <box>
              <size>0.04 0.04 1</size>
            </box>
          </geometry>
          <max_contacts>10</max_contacts>
          <surface>
            <contact>
              <ode/>
            </contact>
            <bounce/>
            <friction>
              <torsional>
                <ode/>
              </torsional>
              <ode/>
            </friction>
          </surface>
        </collision>
        <visual name='leg2_visual'>
          <geometry>
            <box>
              <size>0.04 0.04 1</size>
            </box>
          </geometry>
          <material>
            <script>
              <uri>file://media/materials/scripts/gazebo.material</uri>
              <name>Gazebo/Grey</name>
            </script>
          </material>
        </visual>
        <self_collide>0</self_collide>
        <enable_wind>0</enable_wind>
        <kinematic>0</kinematic>
      </link>
      <link name='leg3'>
        <pose>0.22 -0.22 0.285 0 -0 0</pose>
        <collision name='leg3_collision'>
          <geometry>
            <box>
              <size>0.04 0.04 1</size>
            </box>
          </geometry>
          <max_contacts>10</max_contacts>
          <surface>
            <contact>
              <ode/>
            </contact>
            <bounce/>
            <friction>
              <torsional>
                <ode/>
              </torsional>
              <ode/>
            </friction>
          </surface>
        </collision>
        <visual name='leg3_visual'>
          <geometry>
            <box>
              <size>0.04 0.04 1</size>
            </box>
          </geometry>
          <material>
            <script>
              <uri>file://media/materials/scripts/gazebo.material</uri>
              <name>Gazebo/Grey</name>
            </script>
          </material>
        </visual>
        <self_collide>0</self_collide>
        <enable_wind>0</enable_wind>
        <kinematic>0</kinematic>
      </link>
      <link name='leg4'>
        <pose>-0.22 -0.22 0.285 0 -0 0</pose>
        <collision name='leg4_collision'>
          <geometry>
            <box>
              <size>0.04 0.04 1</size>
            </box>
          </geometry>
          <max_contacts>10</max_contacts>
          <surface>
            <contact>
              <ode/>
            </contact>
            <bounce/>
            <friction>
              <torsional>
                <ode/>
              </torsional>
              <ode/>
            </friction>
          </surface>
        </collision>
        <visual name='leg4_visual'>
          <geometry>
            <box>
              <size>0.04 0.04 1</size>
            </box>
          </geometry>
          <material>
            <script>
              <uri>file://media/materials/scripts/gazebo.material</uri>
              <name>Gazebo/Grey</name>
            </script>
          </material>
        </visual>
        <self_collide>0</self_collide>
        <enable_wind>0</enable_wind>
        <kinematic>0</kinematic>
      </link>
      <pose>0.155634 -0.011566 0 0 -0 0</pose>
    </model>
    <model name='end_table_left'>
      <static>1</static>
      <link name='top_plate'>
        <pose>0 0 0.755 0 -0 0</pose>
        <collision name='top_plate_collision'>
          <geometry>
            <box>
              <size>0.913 0.713 0.04</size>
            </box>
          </geometry>
          <surface>
            <contact>
              <collide_bitmask>1</collide_bitmask>
              <ode/>
            </contact>
            <bounce/>
            <friction>
              <torsional>
                <ode/>
              </torsional>
              <ode/>
            </friction>
          </surface>
          <max_contacts>10</max_contacts>
        </collision>
        <visual name='top_plate_visual'>
          <geometry>
            <box>
              <size>0.913 0.313 0.04</size>
            </box>
          </geometry>
          <material>
            <script>
              <uri>model://end_table_left/materials/scripts</uri>
              <uri>model://end_table_left/materials/textures</uri>
              <name>grid/Image</name>
            </script>
          </material>
        </visual>
        <self_collide>0</self_collide>
        <enable_wind>0</enable_wind>
        <kinematic>0</kinematic>
      </link>
      <link name='leg1'>
        <pose>0.22 -0.1 0.4 0 -0 0</pose>
        <collision name='leg1_collision'>
          <geometry>
            <box>
              <size>0.04 0.04 0.74</size>
            </box>
          </geometry>
          <max_contacts>10</max_contacts>
          <surface>
            <contact>
              <ode/>
            </contact>
            <bounce/>
            <friction>
              <torsional>
                <ode/>
              </torsional>
              <ode/>
            </friction>
          </surface>
        </collision>
        <visual name='leg1_visual'>
          <geometry>
            <box>
              <size>0.04 0.04 0.74</size>
            </box>
          </geometry>
          <material>
            <script>
              <uri>file://media/materials/scripts/gazebo.material</uri>
              <name>Gazebo/White</name>
            </script>
          </material>
        </visual>
        <self_collide>0</self_collide>
        <enable_wind>0</enable_wind>
        <kinematic>0</kinematic>
      </link>
      <link name='leg2'>
        <pose>-0.22 -0.1 0.4 0 -0 0</pose>
        <collision name='leg2_collision'>
          <geometry>
            <box>
              <size>0.04 0.04 0.74</size>
            </box>
          </geometry>
          <max_contacts>10</max_contacts>
          <surface>
            <contact>
              <ode/>
            </contact>
            <bounce/>
            <friction>
              <torsional>
                <ode/>
              </torsional>
              <ode/>
            </friction>
          </surface>
        </collision>
        <visual name='leg2_visual'>
          <geometry>
            <box>
              <size>0.04 0.04 0.74</size>
            </box>
          </geometry>
          <material>
            <script>
              <uri>file://media/materials/scripts/gazebo.material</uri>
              <name>Gazebo/White</name>
            </script>
          </material>
        </visual>
        <self_collide>0</self_collide>
        <enable_wind>0</enable_wind>
        <kinematic>0</kinematic>
      </link>
      <pose>0.249913 -0.52736 0 0 -0 0</pose>
    </model>
    <model name='cafe_table'>
      <static>1</static>
      <link name='link'>
        <collision name='surface'>
          <pose>0 0 0.755 0 -0 0</pose>
          <geometry>
            <box>
              <size>0.913 0.913 0.04</size>
            </box>
          </geometry>
          <max_contacts>10</max_contacts>
          <surface>
            <contact>
              <ode/>
            </contact>
            <bounce/>
            <friction>
              <torsional>
                <ode/>
              </torsional>
              <ode/>
            </friction>
          </surface>
        </collision>
        <collision name='column'>
          <pose>0 0 0.37 0 -0 0</pose>
          <geometry>
            <box>
              <size>0.042 0.042 0.74</size>
            </box>
          </geometry>
          <max_contacts>10</max_contacts>
          <surface>
            <contact>
              <ode/>
            </contact>
            <bounce/>
            <friction>
              <torsional>
                <ode/>
              </torsional>
              <ode/>
            </friction>
          </surface>
        </collision>
        <collision name='base'>
          <pose>0 0 0.02 0 -0 0</pose>
          <geometry>
            <box>
              <size>0.56 0.56 0.04</size>
            </box>
          </geometry>
          <max_contacts>10</max_contacts>
          <surface>
            <contact>
              <ode/>
            </contact>
            <bounce/>
            <friction>
              <torsional>
                <ode/>
              </torsional>
              <ode/>
            </friction>
          </surface>
        </collision>
        <visual name='visual'>
          <geometry>
            <mesh>
              <uri>model://cafe_table/meshes/cafe_table.dae</uri>
            </mesh>
          </geometry>
        </visual>
        <self_collide>0</self_collide>
        <enable_wind>0</enable_wind>
        <kinematic>0</kinematic>
      </link>
      <pose>0.704405 -0.035084 0 0 -0 0</pose>
    </model>
    <state world_name='default'>
      <sim_time>1411 784000000</sim_time>
      <real_time>83 67796982</real_time>
      <wall_time>1657353359 468045546</wall_time>
      <iterations>72505</iterations>
      <model name='X1-Y2-Z2-0'>
        <pose>0.516328 0.159804 0.774304 0.019799 -0.005161 1.62538</pose>
        <scale>1 1 1</scale>
        <link name='link'>
          <pose>0.516328 0.159804 0.774304 0.019799 -0.005161 1.62538</pose>
          <velocity>0 0 0 0 -0 0</velocity>
          <acceleration>0.000511 -0.001092 0.044452 -0.838974 -0.359598 0.100871</acceleration>
          <wrench>5e-06 -1e-05 0.000396 0 -0 0</wrench>
        </link>
      </model>
      <model name='X1-Y2-Z2-CHAMFER-0'>
        <pose>0.341382 0.349884 -1.2e-05 0.001045 0.000256 -0.780481</pose>
        <scale>1 1 1</scale>
        <link name='link'>
          <pose>0.341382 0.349884 -1.2e-05 0.001045 0.000256 -0.780481</pose>
          <velocity>0 0 0 0 -0 0</velocity>
          <acceleration>1e-06 2e-06 0.003386 -0.806605 -0.578036 -0.00084</acceleration>
          <wrench>0 0 3e-05 0 -0 0</wrench>
        </link>
      </model>
      <model name='X1-Y2-Z2-TWINFILLET-0'>
        <pose>0.599192 -0.056437 0.77435 0.01113 -0.019791 -2.18463</pose>
        <scale>1 1 1</scale>
        <link name='link'>
          <pose>0.599192 -0.056437 0.77435 0.01113 -0.019791 -2.18463</pose>
          <velocity>0 0 0 0 -0 0</velocity>
          <acceleration>-0.000151 -0.000419 -0.017631 -0.715686 0.83522 3.07889</acceleration>
          <wrench>-1e-06 -4e-06 -0.000157 0 -0 0</wrench>
        </link>
      </model>
      <model name='X1-Y3-Z2-0'>
        <pose>-0.657716 0.312243 0.002029 0 -0.133472 2.74405</pose>
        <scale>1 1 1</scale>
        <link name='link'>
          <pose>-0.657716 0.312243 0.002029 0 -0.133472 2.74405</pose>
          <velocity>-0.001293 0.000543 -0.0104 -0.2618 -0.623469 -5e-06</velocity>
          <acceleration>-0.00448 0.001793 -0.089418 2.49256 0.340751 -0.030458</acceleration>
          <wrench>-4e-05 1.6e-05 -0.000797 0 -0 0</wrench>
        </link>
      </model>
      <model name='cafe_table'>
        <pose>0.704405 -0.035084 0 0 -0 0</pose>
        <scale>1 1 1</scale>
        <link name='link'>
          <pose>0.704405 -0.035084 0 0 -0 0</pose>
          <velocity>0 0 0 0 -0 0</velocity>
          <acceleration>0 0 0 0 -0 0</acceleration>
          <wrench>0 0 0 0 -0 0</wrench>
        </link>
      </model>
      <model name='end_table_left'>
        <pose>-0.21923 -0.405024 0 0 -0 0</pose>
        <scale>1 1 1</scale>
        <link name='leg1'>
          <pose>0.00077 -0.505024 0.4 0 -0 0</pose>
          <velocity>0 0 0 0 -0 0</velocity>
          <acceleration>0 0 0 0 -0 0</acceleration>
          <wrench>0 0 0 0 -0 0</wrench>
        </link>
        <link name='leg2'>
          <pose>-0.43923 -0.505024 0.4 0 -0 0</pose>
          <velocity>0 0 0 0 -0 0</velocity>
          <acceleration>0 0 0 0 -0 0</acceleration>
          <wrench>0 0 0 0 -0 0</wrench>
        </link>
        <link name='top_plate'>
          <pose>-0.21923 -0.405024 0.755 0 -0 0</pose>
          <velocity>0 0 0 0 -0 0</velocity>
          <acceleration>0 0 0 0 -0 0</acceleration>
          <wrench>0 0 0 0 -0 0</wrench>
        </link>
      </model>
      <model name='end_table_right'>
        <pose>-0.412449 0.199808 0 0 0 -1.57434</pose>
        <scale>1 1 1</scale>
        <link name='leg2'>
          <pose>-0.511669 0.420161 0.4 0 0 -1.57434</pose>
          <velocity>0 0 0 0 -0 0</velocity>
          <acceleration>0 0 0 0 -0 0</acceleration>
          <wrench>0 0 0 0 -0 0</wrench>
        </link>
        <link name='leg_right'>
          <pose>-0.513228 -0.019837 0.4 0 0 -1.57434</pose>
          <velocity>0 0 0 0 -0 0</velocity>
          <acceleration>0 0 0 0 -0 0</acceleration>
          <wrench>0 0 0 0 -0 0</wrench>
        </link>
        <link name='top_plate_right'>
          <pose>-0.412449 0.199808 0.755 0 0 -1.57434</pose>
          <velocity>0 0 0 0 -0 0</velocity>
          <acceleration>0 0 0 0 -0 0</acceleration>
          <wrench>0 0 0 0 -0 0</wrench>
        </link>
      </model>
      <model name='ground_plane'>
        <pose>0 0 0 0 -0 0</pose>
        <scale>1 1 1</scale>
        <link name='link'>
          <pose>0 0 0 0 -0 0</pose>
          <velocity>0 0 0 0 -0 0</velocity>
          <acceleration>0 0 0 0 -0 0</acceleration>
          <wrench>0 0 0 0 -0 0</wrench>
        </link>
      </model>
      <model name='kinect_ros'>
        <pose>1.21541 0.00106 1.11396 1e-06 0.686468 -3.14</pose>
        <scale>1 1 1</scale>
        <link name='link'>
          <pose>1.21541 0.00106 1.11396 1e-06 0.686468 -3.14</pose>
          <velocity>0 0 0 0 -0 0</velocity>
          <acceleration>0 0 0 0 -0 0</acceleration>
          <wrench>0 0 0 0 -0 0</wrench>
        </link>
      </model>
      <model name='robot'>
        <pose>-0 -0 0.9 4.2e-05 -4.3e-05 1e-06</pose>
        <scale>1 1 1</scale>
        <link name='base_link'>
          <pose>-0 -0 0.9 4.2e-05 -4.3e-05 1e-06</pose>
          <velocity>-0 0 -0 -0 -0 -0</velocity>
          <acceleration>-2e-06 5e-06 -1e-06 -0.00038 -0.000914 -0.000282</acceleration>
          <wrench>-7e-06 2.1e-05 -3e-06 0 -0 0</wrench>
        </link>
        <link name='forearm_link'>
          <pose>-0.003852 0.01621 1.41415 -2.26298 1.57061 -2.2631</pose>
          <velocity>0.003239 1e-06 3e-05 1e-06 0.008442 -0.000462</velocity>
          <acceleration>0.000397 -0.000299 0.000162 0.009682 0.000657 0.000203</acceleration>
          <wrench>0.000902 -0.00068 0.000368 0 -0 0</wrench>
        </link>
        <link name='robotiq_85_left_finger_tip_link'>
          <pose>0.434471 0.106957 1.22777 0.765272 1.55776 -0.79646</pose>
          <velocity>0.001758 -7.1e-05 -0.00384 0.000746 0.005428 -0.000361</velocity>
          <acceleration>1.3e-05 0.000445 -4.3e-05 0.000619 0.000699 0.003948</acceleration>
          <wrench>0 9e-06 -1e-06 0 -0 0</wrench>
        </link>
        <link name='robotiq_85_left_inner_knuckle_link'>
          <pose>0.471675 0.107701 1.27115 0.765091 1.55776 -0.796641</pose>
          <velocity>0.001988 -0.000116 -0.004036 0.000748 0.005286 -0.00036</velocity>
          <acceleration>7.3e-05 0.000374 -8.2e-05 0.012556 0.000212 0.00127</acceleration>
          <wrench>2e-06 1.1e-05 -2e-06 0 -0 0</wrench>
        </link>
        <link name='robotiq_85_left_knuckle_link'>
          <pose>0.453715 0.107598 1.2775 0.764706 1.55774 -0.797023</pose>
          <velocity>0.002045 -0.000114 -0.003874 0.000737 0.006392 -0.00037</velocity>
          <acceleration>8e-05 0.00031 -5.2e-05 -0.356227 -1.39345 0.584771</acceleration>
          <wrench>4e-06 1.4e-05 -2e-06 0 -0 0</wrench>
        </link>
        <link name='robotiq_85_right_finger_tip_link'>
          <pose>0.53506 0.107873 1.22868 -2.37568 1.55777 -0.795821</pose>
          <velocity>0.001882 -0.000106 -0.004361 0.000771 0.002676 -0.000335</velocity>
          <acceleration>-2.1e-05 0.000556 -0.000141 0.000386 0.000636 0.004023</acceleration>
          <wrench>-0 1.1e-05 -3e-06 0 -0 0</wrench>
        </link>
        <link name='robotiq_85_right_inner_knuckle_link'>
          <pose>0.497072 0.107932 1.27137 -2.37549 1.55776 -0.795628</pose>
          <velocity>0.00199 -0.000127 -0.004266 0.000773 0.002515 -0.000334</velocity>
          <acceleration>7.2e-05 0.00041 -0.000104 0.008062 0.000166 0.001261</acceleration>
          <wrench>2e-06 1.2e-05 -3e-06 0 -0 0</wrench>
        </link>
        <link name='robotiq_85_right_knuckle_link'>
          <pose>0.514912 0.108156 1.27805 -2.37683 1.55774 -0.796973</pose>
          <velocity>0.00205 -0.000138 -0.004427 0.000715 0.008858 -0.000393</velocity>
          <acceleration>7e-05 0.000454 -0.000133 0.00199 0.000216 0.003102</acceleration>
          <wrench>3e-06 2.1e-05 -6e-06 0 -0 0</wrench>
        </link>
        <link name='shoulder_link'>
          <pose>1e-06 -1e-06 0.989159 -9.2e-05 0.000106 -0.000116</pose>
          <velocity>-0 -0 0 1e-06 1e-06 -0.000461</velocity>
          <acceleration>-3.9e-05 -9.9e-05 1e-06 0.001331 0.001931 0.000291</acceleration>
          <wrench>-0.000146 -0.000367 3e-06 0 -0 0</wrench>
        </link>
        <link name='upper_arm_link'>
          <pose>2.5e-05 0.13585 0.989148 -0.000136 -0.009086 -0.000141</pose>
          <velocity>6.3e-05 -0 0 1e-06 0.007603 -0.000462</velocity>
          <acceleration>0.000169 -0.000493 0.000201 0.001098 0.000664 0.001377</acceleration>
          <wrench>0.001421 -0.004137 0.001683 0 -0 0</wrench>
        </link>
        <link name='wrist_1_link'>
          <pose>0.3884 0.016164 1.41411 -0.01485 1.56171 -0.014959</pose>
          <velocity>0.003238 -0.00018 -0.003282 1e-06 0.009045 -0.000462</velocity>
          <acceleration>0.00026 -2.9e-05 -1.9e-05 0.00165 0.000632 0.001308</acceleration>
          <wrench>0.000318 -3.6e-05 -2.3e-05 0 -0 0</wrench>
        </link>
        <link name='wrist_2_link'>
          <pose>0.388411 0.109166 1.4141 -1.56168 -0.009337 -1.57098</pose>
          <velocity>0.003281 -0.00018 -0.003282 0.000714 0.009045 -0.000456</velocity>
          <acceleration>0.000186 0.00016 -9.3e-05 0.001656 0.000523 0.001317</acceleration>
          <wrench>0.000226 0.000196 -0.000113 0 -0 0</wrench>
        </link>
        <link name='wrist_3_link'>
          <pose>0.483061 0.109158 1.41497 -1.58021 -0.009039 0.009104</pose>
          <velocity>0.003289 -0.000223 -0.004138 0.000713 0.009046 -0.000395</velocity>
          <acceleration>0.000119 0.000288 -9.3e-05 -0.623629 0.142058 -1.88888</acceleration>
          <wrench>9.8e-05 0.000237 -7.7e-05 0 -0 0</wrench>
        </link>
      </model>
      <model name='ur5_base'>
        <pose>0 0 0.110913 0 -0 0</pose>
        <scale>1 1 1</scale>
        <link name='leg1'>
          <pose>0.22 0.22 0.395913 0 -0 0</pose>
          <velocity>0 0 0 0 -0 0</velocity>
          <acceleration>0 0 0 0 -0 0</acceleration>
          <wrench>0 0 0 0 -0 0</wrench>
        </link>
        <link name='leg2'>
          <pose>-0.22 0.22 0.395913 0 -0 0</pose>
          <velocity>0 0 0 0 -0 0</velocity>
          <acceleration>0 0 0 0 -0 0</acceleration>
          <wrench>0 0 0 0 -0 0</wrench>
        </link>
        <link name='leg3'>
          <pose>0.22 -0.22 0.395913 0 -0 0</pose>
          <velocity>0 0 0 0 -0 0</velocity>
          <acceleration>0 0 0 0 -0 0</acceleration>
          <wrench>0 0 0 0 -0 0</wrench>
        </link>
        <link name='leg4'>
          <pose>-0.22 -0.22 0.395913 0 -0 0</pose>
          <velocity>0 0 0 0 -0 0</velocity>
          <acceleration>0 0 0 0 -0 0</acceleration>
          <wrench>0 0 0 0 -0 0</wrench>
        </link>
        <link name='top_plate'>
          <pose>0 0 0.885913 0 -0 0</pose>
          <velocity>0 0 0 0 -0 0</velocity>
          <acceleration>0 0 0 0 -0 0</acceleration>
          <wrench>0 0 0 0 -0 0</wrench>
        </link>
      </model>
      <light name='sun'>
        <pose>0 0 10 0 -0 0</pose>
      </light>
    </state>
    <gui fullscreen='0'>
      <camera name='user_camera'>
        <pose>-0.00802 1.43832 0.926601 0 0.0462 -1.64143</pose>
        <view_controller>orbit</view_controller>
        <projection_type>perspective</projection_type>
      </camera>
    </gui>
    <model name='kinect_ros'>
      <pose>1.64119 -0.022322 0.036 0 -0 0</pose>
      <link name='link'>
        <inertial>
          <mass>0.1</mass>
        </inertial>
        <collision name='collision'>
          <geometry>
            <box>
              <size>0.073 0.276 0.072</size>
            </box>
          </geometry>
          <max_contacts>10</max_contacts>
          <surface>
            <contact>
              <ode/>
            </contact>
            <bounce/>
            <friction>
              <torsional>
                <ode/>
              </torsional>
              <ode/>
            </friction>
          </surface>
        </collision>
        <visual name='visual'>
          <geometry>
            <mesh>
              <uri>model://kinect/meshes/kinect.dae</uri>
            </mesh>
          </geometry>
        </visual>
        <sensor name='camera' type='depth'>
          <update_rate>20</update_rate>
          <camera>
            <horizontal_fov>1.0472</horizontal_fov>
            <image>
              <width>640</width>
              <height>480</height>
              <format>R8G8B8</format>
            </image>
            <clip>
              <near>0.05</near>
              <far>3</far>
            </clip>
          </camera>
          <plugin name='camera_plugin' filename='libgazebo_ros_openni_kinect.so'>
            <baseline>0.2</baseline>
            <alwaysOn>1</alwaysOn>
            <updateRate>0.0</updateRate>
            <cameraName>camera_ir</cameraName>
            <imageTopicName>/camera/color/image_raw</imageTopicName>
            <cameraInfoTopicName>/camera/color/camera_info</cameraInfoTopicName>
            <depthImageTopicName>/camera/depth/image_raw</depthImageTopicName>
            <depthImageCameraInfoTopicName>/camera/depth/camera_info</depthImageCameraInfoTopicName>
            <pointCloudTopicName>/camera/depth/points</pointCloudTopicName>
            <frameName>camera_link</frameName>
            <pointCloudCutoff>0.5</pointCloudCutoff>
            <pointCloudCutoffMax>3.0</pointCloudCutoffMax>
            <distortionK1>0</distortionK1>
            <distortionK2>0</distortionK2>
            <distortionK3>0</distortionK3>
            <distortionT1>0</distortionT1>
            <distortionT2>0</distortionT2>
            <CxPrime>0</CxPrime>
            <Cx>0</Cx>
            <Cy>0</Cy>
            <focalLength>0</focalLength>
            <hackBaseline>0</hackBaseline>
          </plugin>
        </sensor>
        <self_collide>0</self_collide>
        <enable_wind>0</enable_wind>
        <kinematic>0</kinematic>
      </link>
      <static>1</static>
      <gravity>0</gravity>
    </model>
    <model name='robot'>
      <joint name='world_joint' type='fixed'>
        <pose relative_to='__model__'>0 0 0 0 -0 0</pose>
        <parent>world</parent>
        <child>base_link</child>
      </joint>
      <link name='base_link'>
        <pose relative_to='world_joint'>0 0 0 0 -0 0</pose>
        <inertial>
          <pose>0 0 0 0 -0 0</pose>
          <mass>4</mass>
          <inertia>
            <ixx>0.00443333</ixx>
            <ixy>0</ixy>
            <ixz>0</ixz>
            <iyy>0.00443333</iyy>
            <iyz>0</iyz>
            <izz>0.0072</izz>
          </inertia>
        </inertial>
        <collision name='base_link_collision'>
          <pose>0 0 0 0 -0 0</pose>
          <geometry>
            <mesh>
              <scale>1 1 1</scale>
              <uri>/home/gio/lego_recognizer_yolov5/src/arm/meshes/arm/collision/base.stl</uri>
            </mesh>
          </geometry>
          <max_contacts>10</max_contacts>
          <surface>
            <contact>
              <ode/>
            </contact>
            <bounce/>
            <friction>
              <torsional>
                <ode/>
              </torsional>
              <ode/>
            </friction>
          </surface>
        </collision>
        <visual name='base_link_visual'>
          <pose>0 0 0 0 -0 0</pose>
          <geometry>
            <mesh>
              <scale>1 1 1</scale>
              <uri>/home/gio/lego_recognizer_yolov5/src/arm/meshes/arm/visual/base.dae</uri>
            </mesh>
          </geometry>
        </visual>
        <self_collide>0</self_collide>
        <enable_wind>0</enable_wind>
        <kinematic>0</kinematic>
      </link>
      <joint name='shoulder_pan_joint' type='revolute'>
        <pose relative_to='base_link'>0 0 0.089159 0 -0 0</pose>
        <parent>base_link</parent>
        <child>shoulder_link</child>
        <axis>
          <xyz>0 0 1</xyz>
          <limit>
            <lower>-6.28319</lower>
            <upper>6.28319</upper>
            <effort>150</effort>
            <velocity>3.15</velocity>
          </limit>
          <dynamics>
            <damping>0</damping>
            <friction>0</friction>
            <spring_reference>0</spring_reference>
            <spring_stiffness>0</spring_stiffness>
          </dynamics>
        </axis>
      </joint>
      <link name='shoulder_link'>
        <pose relative_to='shoulder_pan_joint'>0 0 0 0 -0 0</pose>
        <inertial>
          <pose>0 0 0 0 -0 0</pose>
          <mass>3.7</mass>
          <inertia>
            <ixx>0.0102675</ixx>
            <ixy>0</ixy>
            <ixz>0</ixz>
            <iyy>0.0102675</iyy>
            <iyz>0</iyz>
            <izz>0.00666</izz>
          </inertia>
        </inertial>
        <collision name='shoulder_link_collision'>
          <pose>0 0 0 0 -0 0</pose>
          <geometry>
            <mesh>
              <scale>1 1 1</scale>
              <uri>/home/gio/lego_recognizer_yolov5/src/arm/meshes/arm/collision/shoulder.stl</uri>
            </mesh>
          </geometry>
          <surface>
            <contact>
              <ode/>
            </contact>
            <friction>
              <ode/>
              <torsional>
                <ode/>
              </torsional>
            </friction>
            <bounce/>
          </surface>
          <max_contacts>10</max_contacts>
        </collision>
        <visual name='shoulder_link_visual'>
          <pose>0 0 0 0 -0 0</pose>
          <geometry>
            <mesh>
              <scale>1 1 1</scale>
              <uri>/home/gio/lego_recognizer_yolov5/src/arm/meshes/arm/visual/shoulder.dae</uri>
            </mesh>
          </geometry>
        </visual>
        <self_collide>1</self_collide>
        <enable_wind>0</enable_wind>
        <kinematic>0</kinematic>
      </link>
      <joint name='shoulder_lift_joint' type='revolute'>
        <pose relative_to='shoulder_link'>0 0.13585 0 3.14159 1.57079 3.14159</pose>
        <parent>shoulder_link</parent>
        <child>upper_arm_link</child>
        <axis>
          <xyz>0 1 0</xyz>
          <limit>
            <lower>-6.28319</lower>
            <upper>6.28319</upper>
            <effort>150</effort>
            <velocity>3.15</velocity>
          </limit>
          <dynamics>
            <damping>0</damping>
            <friction>0</friction>
            <spring_reference>0</spring_reference>
            <spring_stiffness>0</spring_stiffness>
          </dynamics>
        </axis>
      </joint>
      <link name='upper_arm_link'>
        <pose relative_to='shoulder_lift_joint'>0 0 0 0 -0 0</pose>
        <inertial>
          <pose>0 0 0.28 0 -0 0</pose>
          <mass>8.393</mass>
          <inertia>
            <ixx>0.226891</ixx>
            <ixy>0</ixy>
            <ixz>0</ixz>
            <iyy>0.226891</iyy>
            <iyz>0</iyz>
            <izz>0.0151074</izz>
          </inertia>
        </inertial>
        <collision name='upper_arm_link_collision'>
          <pose>0 0 0 0 -0 0</pose>
          <geometry>
            <mesh>
              <scale>1 1 1</scale>
              <uri>/home/gio/lego_recognizer_yolov5/src/arm/meshes/arm/collision/upperarm.stl</uri>
            </mesh>
          </geometry>
          <surface>
            <contact>
              <ode/>
            </contact>
            <friction>
              <ode/>
              <torsional>
                <ode/>
              </torsional>
            </friction>
            <bounce/>
          </surface>
          <max_contacts>10</max_contacts>
        </collision>
        <visual name='upper_arm_link_visual'>
          <pose>0 0 0 0 -0 0</pose>
          <geometry>
            <mesh>
              <scale>1 1 1</scale>
              <uri>/home/gio/lego_recognizer_yolov5/src/arm/meshes/arm/visual/upperarm.dae</uri>
            </mesh>
          </geometry>
        </visual>
        <self_collide>1</self_collide>
        <enable_wind>0</enable_wind>
        <kinematic>0</kinematic>
      </link>
      <joint name='elbow_joint' type='revolute'>
        <pose relative_to='upper_arm_link'>0 -0.1197 0.425 0 -0 0</pose>
        <parent>upper_arm_link</parent>
        <child>forearm_link</child>
        <axis>
          <xyz>0 1 0</xyz>
          <limit>
            <lower>-3.14159</lower>
            <upper>3.14159</upper>
            <effort>150</effort>
            <velocity>3.15</velocity>
          </limit>
          <dynamics>
            <damping>0</damping>
            <friction>0</friction>
            <spring_reference>0</spring_reference>
            <spring_stiffness>0</spring_stiffness>
          </dynamics>
        </axis>
      </joint>
      <link name='forearm_link'>
        <pose relative_to='elbow_joint'>0 0 0 0 -0 0</pose>
        <inertial>
          <pose>0 0 0.196125 0 -0 0</pose>
          <mass>2.275</mass>
          <inertia>
            <ixx>0.0312168</ixx>
            <ixy>0</ixy>
            <ixz>0</ixz>
            <iyy>0.0312168</iyy>
            <iyz>0</iyz>
            <izz>0.004095</izz>
          </inertia>
        </inertial>
        <collision name='forearm_link_collision'>
          <pose>0 0 0 0 -0 0</pose>
          <geometry>
            <mesh>
              <scale>1 1 1</scale>
              <uri>/home/gio/lego_recognizer_yolov5/src/arm/meshes/arm/collision/forearm.stl</uri>
            </mesh>
          </geometry>
          <surface>
            <contact>
              <ode/>
            </contact>
            <friction>
              <ode/>
              <torsional>
                <ode/>
              </torsional>
            </friction>
            <bounce/>
          </surface>
          <max_contacts>10</max_contacts>
        </collision>
        <visual name='forearm_link_visual'>
          <pose>0 0 0 0 -0 0</pose>
          <geometry>
            <mesh>
              <scale>1 1 1</scale>
              <uri>/home/gio/lego_recognizer_yolov5/src/arm/meshes/arm/visual/forearm.dae</uri>
            </mesh>
          </geometry>
        </visual>
        <self_collide>1</self_collide>
        <enable_wind>0</enable_wind>
        <kinematic>0</kinematic>
      </link>
      <joint name='wrist_1_joint' type='revolute'>
        <pose relative_to='forearm_link'>0 0 0.39225 3.14159 1.57079 3.14159</pose>
        <parent>forearm_link</parent>
        <child>wrist_1_link</child>
        <axis>
          <xyz>0 1 0</xyz>
          <limit>
            <lower>-6.28319</lower>
            <upper>6.28319</upper>
            <effort>28</effort>
            <velocity>3.2</velocity>
          </limit>
          <dynamics>
            <damping>0</damping>
            <friction>0</friction>
            <spring_reference>0</spring_reference>
            <spring_stiffness>0</spring_stiffness>
          </dynamics>
        </axis>
      </joint>
      <link name='wrist_1_link'>
        <pose relative_to='wrist_1_joint'>0 0 0 0 -0 0</pose>
        <inertial>
          <pose>0 0.093 0 0 -0 0</pose>
          <mass>1.219</mass>
          <inertia>
            <ixx>0.0025599</ixx>
            <ixy>0</ixy>
            <ixz>0</ixz>
            <iyy>0.0025599</iyy>
            <iyz>0</iyz>
            <izz>0.0021942</izz>
          </inertia>
        </inertial>
        <collision name='wrist_1_link_collision'>
          <pose>0 0 0 0 -0 0</pose>
          <geometry>
            <mesh>
              <scale>1 1 1</scale>
              <uri>/home/gio/lego_recognizer_yolov5/src/arm/meshes/arm/collision/wrist1.stl</uri>
            </mesh>
          </geometry>
          <surface>
            <contact>
              <ode/>
            </contact>
            <friction>
              <ode/>
              <torsional>
                <ode/>
              </torsional>
            </friction>
            <bounce/>
          </surface>
          <max_contacts>10</max_contacts>
        </collision>
        <visual name='wrist_1_link_visual'>
          <pose>0 0 0 0 -0 0</pose>
          <geometry>
            <mesh>
              <scale>1 1 1</scale>
              <uri>/home/gio/lego_recognizer_yolov5/src/arm/meshes/arm/visual/wrist1.dae</uri>
            </mesh>
          </geometry>
        </visual>
        <self_collide>1</self_collide>
        <enable_wind>0</enable_wind>
        <kinematic>0</kinematic>
      </link>
      <joint name='wrist_2_joint' type='revolute'>
        <pose relative_to='wrist_1_link'>0 0.093 0 0 -0 0</pose>
        <parent>wrist_1_link</parent>
        <child>wrist_2_link</child>
        <axis>
          <xyz>0 0 1</xyz>
          <limit>
            <lower>-6.28319</lower>
            <upper>6.28319</upper>
            <effort>28</effort>
            <velocity>3.2</velocity>
          </limit>
          <dynamics>
            <damping>0</damping>
            <friction>0</friction>
            <spring_reference>0</spring_reference>
            <spring_stiffness>0</spring_stiffness>
          </dynamics>
        </axis>
      </joint>
      <link name='wrist_2_link'>
        <pose relative_to='wrist_2_joint'>0 0 0 0 -0 0</pose>
        <inertial>
          <pose>0 0 0.09465 0 -0 0</pose>
          <mass>1.219</mass>
          <inertia>
            <ixx>0.0025599</ixx>
            <ixy>0</ixy>
            <ixz>0</ixz>
            <iyy>0.0025599</iyy>
            <iyz>0</iyz>
            <izz>0.0021942</izz>
          </inertia>
        </inertial>
        <collision name='wrist_2_link_collision'>
          <pose>0 0 0 0 -0 0</pose>
          <geometry>
            <mesh>
              <scale>1 1 1</scale>
              <uri>/home/gio/lego_recognizer_yolov5/src/arm/meshes/arm/collision/wrist2.stl</uri>
            </mesh>
          </geometry>
          <surface>
            <contact>
              <ode/>
            </contact>
            <friction>
              <ode/>
              <torsional>
                <ode/>
              </torsional>
            </friction>
            <bounce/>
          </surface>
          <max_contacts>10</max_contacts>
        </collision>
        <visual name='wrist_2_link_visual'>
          <pose>0 0 0 0 -0 0</pose>
          <geometry>
            <mesh>
              <scale>1 1 1</scale>
              <uri>/home/gio/lego_recognizer_yolov5/src/arm/meshes/arm/visual/wrist2.dae</uri>
            </mesh>
          </geometry>
        </visual>
        <self_collide>1</self_collide>
        <enable_wind>0</enable_wind>
        <kinematic>0</kinematic>
      </link>
      <joint name='wrist_3_joint' type='revolute'>
        <pose relative_to='wrist_2_link'>0 0 0.09465 0 -0 0</pose>
        <parent>wrist_2_link</parent>
        <child>wrist_3_link</child>
        <axis>
          <xyz>0 1 0</xyz>
          <limit>
            <lower>-6.28319</lower>
            <upper>6.28319</upper>
            <effort>28</effort>
            <velocity>3.2</velocity>
          </limit>
          <dynamics>
            <damping>0</damping>
            <friction>0</friction>
            <spring_reference>0</spring_reference>
            <spring_stiffness>0</spring_stiffness>
          </dynamics>
        </axis>
      </joint>
      <link name='wrist_3_link'>
        <pose relative_to='wrist_3_joint'>0 0 0 0 -0 0</pose>
        <inertial>
          <pose>0 0.07837 0 1.5708 -0 0</pose>
          <mass>0.824851</mass>
          <inertia>
            <ixx>0.00123787</ixx>
            <ixy>-5.85795e-35</ixy>
            <ixz>2.06792e-19</ixz>
            <iyy>0.00129887</iyy>
            <iyz>2.36303e-19</iyz>
            <izz>0.000512117</izz>
          </inertia>
        </inertial>
        <collision name='wrist_3_link_collision'>
          <pose>0 0 0 0 -0 0</pose>
          <geometry>
            <mesh>
              <scale>1 1 1</scale>
              <uri>/home/gio/lego_recognizer_yolov5/src/arm/meshes/arm/collision/wrist3.stl</uri>
            </mesh>
          </geometry>
          <surface>
            <contact>
              <ode/>
            </contact>
            <friction>
              <ode/>
              <torsional>
                <ode/>
              </torsional>
            </friction>
            <bounce/>
          </surface>
          <max_contacts>10</max_contacts>
        </collision>
        <collision name='wrist_3_link_fixed_joint_lump__ee_link_collision_1'>
          <pose>-0 0.0723 0 0 -0 1.5708</pose>
          <geometry>
            <box>
              <size>0.01 0.01 0.01</size>
            </box>
          </geometry>
          <surface>
            <contact>
              <ode/>
            </contact>
            <friction>
              <ode/>
              <torsional>
                <ode/>
              </torsional>
            </friction>
            <bounce/>
          </surface>
          <max_contacts>10</max_contacts>
        </collision>
        <collision name='wrist_3_link_fixed_joint_lump__coupler_collision_2'>
          <pose>0 0.0823 0 -1.57079 -1.57079 3.14159</pose>
          <geometry>
            <mesh>
              <scale>1 1 1</scale>
              <uri>/home/gio/lego_recognizer_yolov5/src/arm/meshes/gripper/robotiq_85_coupler.stl</uri>
            </mesh>
          </geometry>
          <max_contacts>10</max_contacts>
          <surface>
            <contact>
              <ode/>
            </contact>
            <bounce/>
            <friction>
              <torsional>
                <ode/>
              </torsional>
              <ode/>
            </friction>
          </surface>
        </collision>
        <collision name='wrist_3_link_fixed_joint_lump__robotiq_85_base_link_collision_3'>
          <pose>0 0.0823 0 0 -0 1.5708</pose>
          <geometry>
            <mesh>
              <scale>1 1 1</scale>
              <uri>/home/gio/lego_recognizer_yolov5/src/arm/meshes/gripper/collision/robotiq_85_base_link.stl</uri>
            </mesh>
          </geometry>
          <max_contacts>10</max_contacts>
          <surface>
            <contact>
              <ode/>
            </contact>
            <bounce/>
            <friction>
              <torsional>
                <ode/>
              </torsional>
              <ode/>
            </friction>
          </surface>
        </collision>
        <visual name='wrist_3_link_visual'>
          <pose>0 0 0 0 -0 0</pose>
          <geometry>
            <mesh>
              <scale>1 1 1</scale>
              <uri>/home/gio/lego_recognizer_yolov5/src/arm/meshes/arm/visual/wrist3.dae</uri>
            </mesh>
          </geometry>
        </visual>
        <visual name='wrist_3_link_fixed_joint_lump__coupler_visual_1'>
          <pose>0 0.0823 0 -1.57079 -1.57079 3.14159</pose>
          <geometry>
            <mesh>
              <scale>1 1 1</scale>
              <uri>/home/gio/lego_recognizer_yolov5/src/arm/meshes/gripper/robotiq_85_coupler.stl</uri>
            </mesh>
          </geometry>
        </visual>
        <visual name='wrist_3_link_fixed_joint_lump__robotiq_85_base_link_visual_2'>
          <pose>0 0.0823 0 0 -0 1.5708</pose>
          <geometry>
            <mesh>
              <scale>1 1 1</scale>
              <uri>/home/gio/lego_recognizer_yolov5/src/arm/meshes/gripper/visual/robotiq_85_base_link.dae</uri>
            </mesh>
          </geometry>
        </visual>
        <self_collide>1</self_collide>
        <enable_wind>0</enable_wind>
        <kinematic>0</kinematic>
      </link>
      <joint name='robotiq_85_left_inner_knuckle_joint' type='revolute'>
        <pose relative_to='wrist_3_link'>-0.0127 0.14372 0 3.14159 -0 1.5708</pose>
        <parent>wrist_3_link</parent>
        <child>robotiq_85_left_inner_knuckle_link</child>
        <axis>
          <xyz>0 0 1</xyz>
          <limit>
            <lower>-3.14</lower>
            <upper>3.14</upper>
            <effort>0.1</effort>
            <velocity>100</velocity>
          </limit>
          <dynamics>
            <spring_reference>0</spring_reference>
            <spring_stiffness>0</spring_stiffness>
          </dynamics>
        </axis>
      </joint>
      <link name='robotiq_85_left_inner_knuckle_link'>
        <pose relative_to='robotiq_85_left_inner_knuckle_joint'>0 0 0 0 -0 0</pose>
        <inertial>
          <pose>0 0 0 0 -0 0</pose>
          <mass>0.029951</mass>
          <inertia>
            <ixx>3.9e-05</ixx>
            <ixy>0</ixy>
            <ixz>0</ixz>
            <iyy>5e-06</iyy>
            <iyz>0</iyz>
            <izz>3.5e-05</izz>
          </inertia>
        </inertial>
        <collision name='robotiq_85_left_inner_knuckle_link_collision'>
          <pose>0 0 0 0 -0 0</pose>
          <geometry>
            <mesh>
              <scale>1 1 1</scale>
              <uri>/home/gio/lego_recognizer_yolov5/src/arm/meshes/gripper/collision/robotiq_85_inner_knuckle_link.stl</uri>
            </mesh>
          </geometry>
          <max_contacts>10</max_contacts>
          <surface>
            <contact>
              <ode/>
            </contact>
            <bounce/>
            <friction>
              <torsional>
                <ode/>
              </torsional>
              <ode/>
            </friction>
          </surface>
        </collision>
        <visual name='robotiq_85_left_inner_knuckle_link_visual'>
          <pose>0 0 0 0 -0 0</pose>
          <geometry>
            <mesh>
              <scale>1 1 1</scale>
              <uri>/home/gio/lego_recognizer_yolov5/src/arm/meshes/gripper/visual/robotiq_85_inner_knuckle_link.dae</uri>
            </mesh>
          </geometry>
        </visual>
        <self_collide>0</self_collide>
        <enable_wind>0</enable_wind>
        <kinematic>0</kinematic>
      </link>
      <joint name='robotiq_85_left_finger_tip_joint' type='revolute'>
        <pose relative_to='robotiq_85_left_inner_knuckle_link'>0.04304 -0.037599 0 0 -0 0</pose>
        <parent>robotiq_85_left_inner_knuckle_link</parent>
        <child>robotiq_85_left_finger_tip_link</child>
        <axis>
          <xyz>0 0 1</xyz>
          <limit>
            <lower>-3.14</lower>
            <upper>3.14</upper>
            <effort>0.1</effort>
            <velocity>100</velocity>
          </limit>
          <dynamics>
            <spring_reference>0</spring_reference>
            <spring_stiffness>0</spring_stiffness>
          </dynamics>
        </axis>
      </joint>
      <link name='robotiq_85_left_finger_tip_link'>
        <pose relative_to='robotiq_85_left_finger_tip_joint'>0 0 0 0 -0 0</pose>
        <inertial>
          <pose>0 0 0 0 -0 0</pose>
          <mass>0.019555</mass>
          <inertia>
            <ixx>2e-06</ixx>
            <ixy>0</ixy>
            <ixz>0</ixz>
            <iyy>5e-06</iyy>
            <iyz>0</iyz>
            <izz>6e-06</izz>
          </inertia>
        </inertial>
        <collision name='robotiq_85_left_finger_tip_link_collision'>
          <pose>0 0 0 0 -0 0</pose>
          <geometry>
            <mesh>
              <scale>1 1 1</scale>
              <uri>/home/gio/lego_recognizer_yolov5/src/arm/meshes/gripper/collision/robotiq_85_finger_tip_link.stl</uri>
            </mesh>
          </geometry>
          <surface>
            <contact>
              <ode>
                <kp>1e+06</kp>
                <kd>1</kd>
                <min_depth>0.001</min_depth>
              </ode>
            </contact>
            <friction>
              <ode>
                <mu>1</mu>
                <mu2>1</mu2>
              </ode>
              <torsional>
                <ode/>
              </torsional>
            </friction>
            <bounce/>
          </surface>
          <max_contacts>10</max_contacts>
        </collision>
        <visual name='robotiq_85_left_finger_tip_link_visual'>
          <pose>0 0 0 0 -0 0</pose>
          <geometry>
            <mesh>
              <scale>1 1 1</scale>
              <uri>/home/gio/lego_recognizer_yolov5/src/arm/meshes/gripper/visual/robotiq_85_finger_tip_link.dae</uri>
            </mesh>
          </geometry>
        </visual>
        <self_collide>0</self_collide>
        <enable_wind>0</enable_wind>
        <kinematic>0</kinematic>
      </link>
      <joint name='robotiq_85_left_knuckle_joint' type='revolute'>
        <pose relative_to='wrist_3_link'>-0.030601 0.137205 0 3.14159 -0 1.5708</pose>
        <parent>wrist_3_link</parent>
        <child>robotiq_85_left_knuckle_link</child>
        <axis>
          <xyz>0 0 1</xyz>
          <limit>
            <lower>0</lower>
            <upper>0.80285</upper>
            <effort>1000</effort>
            <velocity>0.5</velocity>
          </limit>
          <dynamics>
            <spring_reference>0</spring_reference>
            <spring_stiffness>0</spring_stiffness>
          </dynamics>
        </axis>
      </joint>
      <link name='robotiq_85_left_knuckle_link'>
        <pose relative_to='robotiq_85_left_knuckle_joint'>0 0 0 0 -0 0</pose>
        <inertial>
          <pose>-0.002436 -0.018774 0 0 -0 0</pose>
          <mass>0.0458</mass>
          <inertia>
            <ixx>2.29304e-05</ixx>
            <ixy>-4.4183e-06</ixy>
            <ixz>0</ixz>
            <iyy>2.2184e-05</iyy>
            <iyz>0</iyz>
            <izz>4.11145e-05</izz>
          </inertia>
        </inertial>
        <collision name='robotiq_85_left_knuckle_link_collision'>
          <pose>0 0 0 0 -0 0</pose>
          <geometry>
            <mesh>
              <scale>1 1 1</scale>
              <uri>/home/gio/lego_recognizer_yolov5/src/arm/meshes/gripper/collision/robotiq_85_knuckle_link.stl</uri>
            </mesh>
          </geometry>
          <max_contacts>10</max_contacts>
          <surface>
            <contact>
              <ode/>
            </contact>
            <bounce/>
            <friction>
              <torsional>
                <ode/>
              </torsional>
              <ode/>
            </friction>
          </surface>
        </collision>
        <collision name='robotiq_85_left_knuckle_link_fixed_joint_lump__robotiq_85_left_finger_link_collision_1'>
          <pose>-0.004086 -0.031486 0 0 -0 0</pose>
          <geometry>
            <mesh>
              <scale>1 1 1</scale>
              <uri>/home/gio/lego_recognizer_yolov5/src/arm/meshes/gripper/collision/robotiq_85_finger_link.stl</uri>
            </mesh>
          </geometry>
          <max_contacts>10</max_contacts>
          <surface>
            <contact>
              <ode/>
            </contact>
            <bounce/>
            <friction>
              <torsional>
                <ode/>
              </torsional>
              <ode/>
            </friction>
          </surface>
        </collision>
        <visual name='robotiq_85_left_knuckle_link_visual'>
          <pose>0 0 0 0 -0 0</pose>
          <geometry>
            <mesh>
              <scale>1 1 1</scale>
              <uri>/home/gio/lego_recognizer_yolov5/src/arm/meshes/gripper/visual/robotiq_85_knuckle_link.dae</uri>
            </mesh>
          </geometry>
        </visual>
        <visual name='robotiq_85_left_knuckle_link_fixed_joint_lump__robotiq_85_left_finger_link_visual_1'>
          <pose>-0.004086 -0.031486 0 0 -0 0</pose>
          <geometry>
            <mesh>
              <scale>1 1 1</scale>
              <uri>/home/gio/lego_recognizer_yolov5/src/arm/meshes/gripper/visual/robotiq_85_finger_link.dae</uri>
            </mesh>
          </geometry>
        </visual>
        <self_collide>0</self_collide>
        <enable_wind>0</enable_wind>
        <kinematic>0</kinematic>
      </link>
      <joint name='robotiq_85_right_inner_knuckle_joint' type='revolute'>
        <pose relative_to='wrist_3_link'>0.0127 0.14372 0 0 -0 1.5708</pose>
        <parent>wrist_3_link</parent>
        <child>robotiq_85_right_inner_knuckle_link</child>
        <axis>
          <xyz>0 0 1</xyz>
          <limit>
            <lower>-3.14</lower>
            <upper>3.14</upper>
            <effort>0.1</effort>
            <velocity>100</velocity>
          </limit>
          <dynamics>
            <spring_reference>0</spring_reference>
            <spring_stiffness>0</spring_stiffness>
          </dynamics>
        </axis>
      </joint>
      <link name='robotiq_85_right_inner_knuckle_link'>
        <pose relative_to='robotiq_85_right_inner_knuckle_joint'>0 0 0 0 -0 0</pose>
        <inertial>
          <pose>0 0 0 0 -0 0</pose>
          <mass>0.029951</mass>
          <inertia>
            <ixx>3.9e-05</ixx>
            <ixy>0</ixy>
            <ixz>0</ixz>
            <iyy>5e-06</iyy>
            <iyz>0</iyz>
            <izz>3.5e-05</izz>
          </inertia>
        </inertial>
        <collision name='robotiq_85_right_inner_knuckle_link_collision'>
          <pose>0 0 0 0 -0 0</pose>
          <geometry>
            <mesh>
              <scale>1 1 1</scale>
              <uri>/home/gio/lego_recognizer_yolov5/src/arm/meshes/gripper/collision/robotiq_85_inner_knuckle_link.stl</uri>
            </mesh>
          </geometry>
          <max_contacts>10</max_contacts>
          <surface>
            <contact>
              <ode/>
            </contact>
            <bounce/>
            <friction>
              <torsional>
                <ode/>
              </torsional>
              <ode/>
            </friction>
          </surface>
        </collision>
        <visual name='robotiq_85_right_inner_knuckle_link_visual'>
          <pose>0 0 0 0 -0 0</pose>
          <geometry>
            <mesh>
              <scale>1 1 1</scale>
              <uri>/home/gio/lego_recognizer_yolov5/src/arm/meshes/gripper/visual/robotiq_85_inner_knuckle_link.dae</uri>
            </mesh>
          </geometry>
        </visual>
        <self_collide>0</self_collide>
        <enable_wind>0</enable_wind>
        <kinematic>0</kinematic>
      </link>
      <joint name='robotiq_85_right_finger_tip_joint' type='revolute'>
        <pose relative_to='robotiq_85_right_inner_knuckle_link'>0.04304 -0.037599 0 0 -0 0</pose>
        <parent>robotiq_85_right_inner_knuckle_link</parent>
        <child>robotiq_85_right_finger_tip_link</child>
        <axis>
          <xyz>0 0 1</xyz>
          <limit>
            <lower>-3.14</lower>
            <upper>3.14</upper>
            <effort>0.1</effort>
            <velocity>100</velocity>
          </limit>
          <dynamics>
            <spring_reference>0</spring_reference>
            <spring_stiffness>0</spring_stiffness>
          </dynamics>
        </axis>
      </joint>
      <link name='robotiq_85_right_finger_tip_link'>
        <pose relative_to='robotiq_85_right_finger_tip_joint'>0 0 0 0 -0 0</pose>
        <inertial>
          <pose>0 0 0 0 -0 0</pose>
          <mass>0.019555</mass>
          <inertia>
            <ixx>2e-06</ixx>
            <ixy>0</ixy>
            <ixz>0</ixz>
            <iyy>5e-06</iyy>
            <iyz>0</iyz>
            <izz>6e-06</izz>
          </inertia>
        </inertial>
        <collision name='robotiq_85_right_finger_tip_link_collision'>
          <pose>0 0 0 0 -0 0</pose>
          <geometry>
            <mesh>
              <scale>1 1 1</scale>
              <uri>/home/gio/lego_recognizer_yolov5/src/arm/meshes/gripper/collision/robotiq_85_finger_tip_link.stl</uri>
            </mesh>
          </geometry>
          <surface>
            <contact>
              <ode>
                <kp>1e+06</kp>
                <kd>1</kd>
                <min_depth>0.001</min_depth>
              </ode>
            </contact>
            <friction>
              <ode>
                <mu>1</mu>
                <mu2>1</mu2>
              </ode>
              <torsional>
                <ode/>
              </torsional>
            </friction>
            <bounce/>
          </surface>
          <max_contacts>10</max_contacts>
        </collision>
        <visual name='robotiq_85_right_finger_tip_link_visual'>
          <pose>0 0 0 0 -0 0</pose>
          <geometry>
            <mesh>
              <scale>1 1 1</scale>
              <uri>/home/gio/lego_recognizer_yolov5/src/arm/meshes/gripper/visual/robotiq_85_finger_tip_link.dae</uri>
            </mesh>
          </geometry>
        </visual>
        <self_collide>0</self_collide>
        <enable_wind>0</enable_wind>
        <kinematic>0</kinematic>
      </link>
      <joint name='robotiq_85_right_knuckle_joint' type='revolute'>
        <pose relative_to='wrist_3_link'>0.030601 0.137205 0 0 -0 1.5708</pose>
        <parent>wrist_3_link</parent>
        <child>robotiq_85_right_knuckle_link</child>
        <axis>
          <xyz>0 0 1</xyz>
          <limit>
            <lower>-3.14</lower>
            <upper>3.14</upper>
            <effort>1000</effort>
            <velocity>100</velocity>
          </limit>
          <dynamics>
            <spring_reference>0</spring_reference>
            <spring_stiffness>0</spring_stiffness>
          </dynamics>
        </axis>
      </joint>
      <link name='robotiq_85_right_knuckle_link'>
        <pose relative_to='robotiq_85_right_knuckle_joint'>0 0 0 0 -0 0</pose>
        <inertial>
          <pose>-0.002436 -0.018774 0 0 -0 0</pose>
          <mass>0.0458</mass>
          <inertia>
            <ixx>2.29304e-05</ixx>
            <ixy>-4.4183e-06</ixy>
            <ixz>0</ixz>
            <iyy>2.2184e-05</iyy>
            <iyz>0</iyz>
            <izz>4.11145e-05</izz>
          </inertia>
        </inertial>
        <collision name='robotiq_85_right_knuckle_link_collision'>
          <pose>0 0 0 0 -0 0</pose>
          <geometry>
            <mesh>
              <scale>1 1 1</scale>
              <uri>/home/gio/lego_recognizer_yolov5/src/arm/meshes/gripper/collision/robotiq_85_knuckle_link.stl</uri>
            </mesh>
          </geometry>
          <max_contacts>10</max_contacts>
          <surface>
            <contact>
              <ode/>
            </contact>
            <bounce/>
            <friction>
              <torsional>
                <ode/>
              </torsional>
              <ode/>
            </friction>
          </surface>
        </collision>
        <collision name='robotiq_85_right_knuckle_link_fixed_joint_lump__robotiq_85_right_finger_link_collision_1'>
          <pose>-0.004086 -0.031486 0 0 -0 0</pose>
          <geometry>
            <mesh>
              <scale>1 1 1</scale>
              <uri>/home/gio/lego_recognizer_yolov5/src/arm/meshes/gripper/collision/robotiq_85_finger_link.stl</uri>
            </mesh>
          </geometry>
          <max_contacts>10</max_contacts>
          <surface>
            <contact>
              <ode/>
            </contact>
            <bounce/>
            <friction>
              <torsional>
                <ode/>
              </torsional>
              <ode/>
            </friction>
          </surface>
        </collision>
        <visual name='robotiq_85_right_knuckle_link_visual'>
          <pose>0 0 0 0 -0 0</pose>
          <geometry>
            <mesh>
              <scale>1 1 1</scale>
              <uri>/home/gio/lego_recognizer_yolov5/src/arm/meshes/gripper/visual/robotiq_85_knuckle_link.dae</uri>
            </mesh>
          </geometry>
        </visual>
        <visual name='robotiq_85_right_knuckle_link_fixed_joint_lump__robotiq_85_right_finger_link_visual_1'>
          <pose>-0.004086 -0.031486 0 0 -0 0</pose>
          <geometry>
            <mesh>
              <scale>1 1 1</scale>
              <uri>/home/gio/lego_recognizer_yolov5/src/arm/meshes/gripper/visual/robotiq_85_finger_link.dae</uri>
            </mesh>
          </geometry>
        </visual>
        <self_collide>0</self_collide>
        <enable_wind>0</enable_wind>
        <kinematic>0</kinematic>
      </link>
      <plugin name='ros_control' filename='libgazebo_ros_control.so'>
        <robotNamespace>/</robotNamespace>
      </plugin>
      <static>0</static>
      <plugin name='mimic_robotiq_85_1' filename='libroboticsgroup_upatras_gazebo_mimic_joint_plugin.so'>
        <joint>robotiq_85_left_knuckle_joint</joint>
        <mimicJoint>robotiq_85_right_knuckle_joint</mimicJoint>
        <robotNamespace>/</robotNamespace>
      </plugin>
      <plugin name='mimic_robotiq_85_2' filename='libroboticsgroup_upatras_gazebo_mimic_joint_plugin.so'>
        <joint>robotiq_85_left_knuckle_joint</joint>
        <mimicJoint>robotiq_85_left_inner_knuckle_joint</mimicJoint>
        <robotNamespace>/</robotNamespace>
      </plugin>
      <plugin name='mimic_robotiq_85_3' filename='libroboticsgroup_upatras_gazebo_mimic_joint_plugin.so'>
        <joint>robotiq_85_left_knuckle_joint</joint>
        <mimicJoint>robotiq_85_right_inner_knuckle_joint</mimicJoint>
        <robotNamespace>/</robotNamespace>
      </plugin>
      <plugin name='mimic_robotiq_85_4' filename='libroboticsgroup_upatras_gazebo_mimic_joint_plugin.so'>
        <joint>robotiq_85_left_knuckle_joint</joint>
        <mimicJoint>robotiq_85_left_finger_tip_joint</mimicJoint>
        <multiplier>-1.0</multiplier>
        <offset>0.0</offset>
        <robotNamespace>/</robotNamespace>
      </plugin>
      <plugin name='mimic_robotiq_85_5' filename='libroboticsgroup_upatras_gazebo_mimic_joint_plugin.so'>
        <joint>robotiq_85_left_knuckle_joint</joint>
        <mimicJoint>robotiq_85_right_finger_tip_joint</mimicJoint>
        <multiplier>-1.0</multiplier>
        <offset>0.0</offset>
        <robotNamespace>/</robotNamespace>
      </plugin>
      <pose>0 0 0.9 0 -0 0</pose>
    </model>
    <model name='end_table_right'>
      <static>1</static>
      <link name='top_plate_right'>
        <pose>0 0 0.755 0 -0 0</pose>
        <collision name='top_plate_collision'>
          <geometry>
            <box>
              <size>0.913 0.713 0.04</size>
            </box>
          </geometry>
          <surface>
            <contact>
              <collide_bitmask>1</collide_bitmask>
              <ode/>
            </contact>
            <bounce/>
            <friction>
              <torsional>
                <ode/>
              </torsional>
              <ode/>
            </friction>
          </surface>
          <max_contacts>10</max_contacts>
        </collision>
        <visual name='top_plate_visual'>
          <geometry>
            <box>
              <size>0.913 0.313 0.04</size>
            </box>
          </geometry>
          <material>
            <script>
              <uri>model://end_table_right/materials/scripts</uri>
              <uri>model://end_table_right/materials/textures</uri>
              <name>grid/Image1</name>
            </script>
          </material>
        </visual>
        <self_collide>0</self_collide>
        <enable_wind>0</enable_wind>
        <kinematic>0</kinematic>
      </link>
      <link name='leg_right'>
        <pose>0.22 -0.1 0.4 0 -0 0</pose>
        <collision name='leg_right_collision'>
          <geometry>
            <box>
              <size>0.04 0.04 0.74</size>
            </box>
          </geometry>
          <max_contacts>10</max_contacts>
          <surface>
            <contact>
              <ode/>
            </contact>
            <bounce/>
            <friction>
              <torsional>
                <ode/>
              </torsional>
              <ode/>
            </friction>
          </surface>
        </collision>
        <visual name='leg_right_visual'>
          <geometry>
            <box>
              <size>0.04 0.04 0.74</size>
            </box>
          </geometry>
          <material>
            <script>
              <uri>file://media/materials/scripts/gazebo.material</uri>
              <name>Gazebo/White</name>
            </script>
          </material>
        </visual>
        <self_collide>0</self_collide>
        <enable_wind>0</enable_wind>
        <kinematic>0</kinematic>
      </link>
      <link name='leg2'>
        <pose>-0.22 -0.1 0.4 0 -0 0</pose>
        <collision name='leg2_collision'>
          <geometry>
            <box>
              <size>0.04 0.04 0.74</size>
            </box>
          </geometry>
          <max_contacts>10</max_contacts>
          <surface>
            <contact>
              <ode/>
            </contact>
            <bounce/>
            <friction>
              <torsional>
                <ode/>
              </torsional>
              <ode/>
            </friction>
          </surface>
        </collision>
        <visual name='leg2_visual'>
          <geometry>
            <box>
              <size>0.04 0.04 0.74</size>
            </box>
          </geometry>
          <material>
            <script>
              <uri>file://media/materials/scripts/gazebo.material</uri>
              <name>Gazebo/White</name>
            </script>
          </material>
        </visual>
        <self_collide>0</self_collide>
        <enable_wind>0</enable_wind>
        <kinematic>0</kinematic>
      </link>
      <pose>-0.769156 0.352848 0 0 -0 0</pose>
    </model>
    <model name='X1-Y2-Z2-CHAMFER-0'>
      <link name='link'>
        <inertial>
          <mass>0.00891495</mass>
          <inertia>
            <ixx>0.000598</ixx>
            <ixy>0</ixy>
            <ixz>-0</ixz>
            <iyy>0.000235</iyy>
            <iyz>-0</iyz>
            <izz>0.000501</izz>
          </inertia>
          <pose>0 0 0 0 -0 0</pose>
        </inertial>
        <collision name='collision'>
          <geometry>
            <mesh>
              <scale>1 1 1</scale>
              <uri>model://X1-Y2-Z2-CHAMFER/meshes/X1-Y2-Z2-CHAMFER.stl</uri>
            </mesh>
          </geometry>
          <surface>
            <contact>
              <poissons_ratio>0.347</poissons_ratio>
              <elastic_modulus>8.8e+09</elastic_modulus>
              <ode>
                <kp>100000</kp>
                <kd>1</kd>
                <max_vel>1</max_vel>
                <min_depth>0.001</min_depth>
              </ode>
            </contact>
            <friction>
              <torsional>
                <coefficient>1</coefficient>
                <use_patch_radius>0</use_patch_radius>
                <surface_radius>0.05</surface_radius>
                <ode/>
              </torsional>
              <ode/>
            </friction>
            <bounce/>
          </surface>
          <max_contacts>10</max_contacts>
        </collision>
        <visual name='visual'>
          <geometry>
            <mesh>
              <scale>1 1 1</scale>
              <uri>model://X1-Y2-Z2-CHAMFER/meshes/X1-Y2-Z2-CHAMFER.stl</uri>
            </mesh>
          </geometry>
          <material>
            <script>
              <uri>file://media/materials/scripts/gazebo.material</uri>
              <name>Gazebo/Grey</name>
            </script>
            <shader type='vertex'>
              <normal_map>__default__</normal_map>
            </shader>
            <ambient>0.29 0.58 0.79 1</ambient>
            <diffuse>0.7 0.7 0.7 1</diffuse>
            <specular>0.01 0.01 0.01 1</specular>
            <emissive>0 0 0 1</emissive>
          </material>
        </visual>
        <self_collide>0</self_collide>
        <enable_wind>0</enable_wind>
        <kinematic>0</kinematic>
        <origin pose='0 0 0 0 0 0'/>
      </link>
      <pose>0.405926 0.249855 0.775 0 0 -0.356408</pose>
    </model>
    <model name='X1-Y3-Z2-0'>
      <link name='link'>
        <inertial>
          <mass>0.00891495</mass>
          <inertia>
            <ixx>0.000598</ixx>
            <ixy>0</ixy>
            <ixz>-0</ixz>
            <iyy>0.000235</iyy>
            <iyz>-0</iyz>
            <izz>0.000501</izz>
          </inertia>
          <pose>0 0 0 0 -0 0</pose>
        </inertial>
        <collision name='collision'>
          <geometry>
            <mesh>
              <scale>1 1 1</scale>
              <uri>model://X1-Y3-Z2/meshes/X1-Y3-Z2.stl</uri>
            </mesh>
          </geometry>
          <surface>
            <contact>
              <poissons_ratio>0.347</poissons_ratio>
              <elastic_modulus>8.8e+09</elastic_modulus>
              <ode>
                <kp>100000</kp>
                <kd>1</kd>
                <max_vel>1</max_vel>
                <min_depth>0.001</min_depth>
              </ode>
            </contact>
            <friction>
              <torsional>
                <coefficient>1</coefficient>
                <use_patch_radius>0</use_patch_radius>
                <surface_radius>0.05</surface_radius>
                <ode/>
              </torsional>
              <ode/>
            </friction>
            <bounce/>
          </surface>
          <max_contacts>10</max_contacts>
        </collision>
        <visual name='visual'>
          <geometry>
            <mesh>
              <scale>1 1 1</scale>
              <uri>model://X1-Y3-Z2/meshes/X1-Y3-Z2.stl</uri>
            </mesh>
          </geometry>
          <material>
            <script>
              <uri>file://media/materials/scripts/gazebo.material</uri>
              <name>Gazebo/Grey</name>
            </script>
            <shader type='vertex'>
              <normal_map>__default__</normal_map>
            </shader>
            <ambient>0.29 0.58 0.79 1</ambient>
            <diffuse>0.7 0.7 0.7 1</diffuse>
            <specular>0.01 0.01 0.01 1</specular>
            <emissive>0 0 0 1</emissive>
          </material>
        </visual>
        <self_collide>0</self_collide>
        <enable_wind>0</enable_wind>
        <kinematic>0</kinematic>
        <origin pose='0 0 0 0 0 0'/>
      </link>
      <pose>0.650829 0.239998 0.775 0 -0 -2.92795</pose>
    </model>
    <model name='X1-Y2-Z2-TWINFILLET-0'>
      <link name='link'>
        <inertial>
          <mass>0.00891495</mass>
          <inertia>
            <ixx>0.000598</ixx>
            <ixy>0</ixy>
            <ixz>-0</ixz>
            <iyy>0.000235</iyy>
            <iyz>-0</iyz>
            <izz>0.000501</izz>
          </inertia>
          <pose>0 0 0 0 -0 0</pose>
        </inertial>
        <collision name='collision'>
          <geometry>
            <mesh>
              <scale>1 1 1</scale>
              <uri>model://X1-Y2-Z2-TWINFILLET/meshes/X1-Y2-Z2-TWINFILLET.stl</uri>
            </mesh>
          </geometry>
          <surface>
            <contact>
              <poissons_ratio>0.347</poissons_ratio>
              <elastic_modulus>8.8e+09</elastic_modulus>
              <ode>
                <kp>100000</kp>
                <kd>1</kd>
                <max_vel>1</max_vel>
                <min_depth>0.001</min_depth>
              </ode>
            </contact>
            <friction>
              <torsional>
                <coefficient>1</coefficient>
                <use_patch_radius>0</use_patch_radius>
                <surface_radius>0.05</surface_radius>
                <ode/>
              </torsional>
              <ode/>
            </friction>
            <bounce/>
          </surface>
          <max_contacts>10</max_contacts>
        </collision>
        <visual name='visual'>
          <geometry>
            <mesh>
              <scale>1 1 1</scale>
              <uri>model://X1-Y2-Z2-TWINFILLET/meshes/X1-Y2-Z2-TWINFILLET.stl</uri>
            </mesh>
          </geometry>
          <material>
            <script>
              <uri>file://media/materials/scripts/gazebo.material</uri>
              <name>Gazebo/Grey</name>
            </script>
            <shader type='vertex'>
              <normal_map>__default__</normal_map>
            </shader>
            <ambient>0.29 0.58 0.79 1</ambient>
            <diffuse>0.7 0.7 0.7 1</diffuse>
            <specular>0.01 0.01 0.01 1</specular>
            <emissive>0 0 0 1</emissive>
          </material>
        </visual>
        <self_collide>0</self_collide>
        <enable_wind>0</enable_wind>
        <kinematic>0</kinematic>
        <origin pose='0 0 0 0 0 0'/>
      </link>
      <pose>0.599189 -0.056432 0.775 0 0 -2.1844</pose>
    </model>
    <model name='X1-Y2-Z2-0'>
      <link name='link'>
        <inertial>
          <mass>0.00891495</mass>
          <inertia>
            <ixx>0.000598</ixx>
            <ixy>0</ixy>
            <ixz>-0</ixz>
            <iyy>0.000235</iyy>
            <iyz>-0</iyz>
            <izz>0.000501</izz>
          </inertia>
          <pose>0 0 0 0 -0 0</pose>
        </inertial>
        <collision name='collision'>
          <geometry>
            <mesh>
              <scale>1 1 1</scale>
              <uri>model://X1-Y2-Z2/meshes/X1-Y2-Z2.stl</uri>
            </mesh>
          </geometry>
          <surface>
            <contact>
              <poissons_ratio>0.347</poissons_ratio>
              <elastic_modulus>8.8e+09</elastic_modulus>
              <ode>
                <kp>100000</kp>
                <kd>1</kd>
                <max_vel>1</max_vel>
                <min_depth>0.001</min_depth>
              </ode>
            </contact>
            <friction>
              <torsional>
                <coefficient>1</coefficient>
                <use_patch_radius>0</use_patch_radius>
                <surface_radius>0.05</surface_radius>
                <ode/>
              </torsional>
              <ode/>
            </friction>
            <bounce/>
          </surface>
          <max_contacts>10</max_contacts>
        </collision>
        <visual name='visual'>
          <geometry>
            <mesh>
              <scale>1 1 1</scale>
              <uri>model://X1-Y2-Z2/meshes/X1-Y2-Z2.stl</uri>
            </mesh>
          </geometry>
          <material>
            <script>
              <uri>file://media/materials/scripts/gazebo.material</uri>
              <name>Gazebo/Grey</name>
            </script>
            <shader type='vertex'>
              <normal_map>__default__</normal_map>
            </shader>
            <ambient>0.29 0.58 0.79 1</ambient>
            <diffuse>0.7 0.7 0.7 1</diffuse>
            <specular>0.01 0.01 0.01 1</specular>
            <emissive>0 0 0 1</emissive>
          </material>
        </visual>
        <self_collide>0</self_collide>
        <enable_wind>0</enable_wind>
        <kinematic>0</kinematic>
        <origin pose='0 0 0 0 0 0'/>
      </link>
      <pose>0.516334 0.159802 0.775 0 -0 1.62542</pose>
    </model>
  </world>
</sdf>
